Workbook

Sheet LEIA-ME
B2: Preços de energia por estado — tratamento de dados
B3: Insumo para a aba Fuel_Prices_State do Model_Config_12 (modelo v20_12)
B5: COMO USAR
B6: 1. Vá em "Premissas" e confira/ajuste as células amarelas (ano-base, câmbio, poder calorífico, tributos, faixa de consumo).
B7: 2. Em "EE_ANEEL", confira a coluna UF e a coluna Peso. Peso 1 = a distribuidora entra na média do estado; 0 = não entra.
B8: 3. A aba "Fuel_Prices_State" recalcula sozinha. Copie as colunas A:D e cole na aba de mesmo nome do Model_Config_12.
B10: CONVENÇÃO DE COR
B11: Amarelo = célula de entrada, você edita. Azul = número fixo digitado (premissa). Preto = fórmula. Verde = link de outra aba.
B13: DECISÕES METODOLÓGICAS EMBUTIDAS (todas revisáveis em "Premissas")
B14: • Ano-base: 2024. É o ano completo mais recente, tem média anual publicada nos dois lados (ANEEL e Boletim do Gás), e antecede o choque de preços de 2025-26. Alternativas: 2022, 2023 ou a média 2022-2024.
B15: • Eletricidade — filtro ANEEL: Subgrupo A4, modalidade Verde, Tarifa de Aplicação, Detalhe "Não se aplica", posto Fora ponta, unidade MWh. Preço = TUSD + TE. ATENÇÃO: não existe classe "Industrial" no dado da ANEEL — no Grupo A a tarifa não diferencia por classe, e indústria cai em "Não se aplica". O recorte industrial se faz pelo SUBGRUPO (tensão), não pela classe.
B16: • Por que A4 e não A3/A2: a modalidade Verde só existe até o subgrupo A4 (acima disso, só Azul). A4 é, portanto, o maior nível de tensão em que a comparação Verde é possível. Plantas muito grandes conectam em A3/A2 e pagam menos — ver pendências.
... B65: - Trabalho futuro registrado: briquete verde da Vale (2 usinas em Tubarão, ~6 Mt/ano) como aglomeração alternativa p/ DR — hoje reforça a âncora ES.

Sheet Premissas
B2: Premissas
B4: Premissa | C4: Valor | D4: Nota / fonte
B5: ANO-BASE
B6: Ano de referência | C6: 2024 | D6: Digite 2022, 2023, 2024 ou 0 para média 2022-2024. Recomendado: 2024.
B7: CÂMBIO (média anual R$/US$)
B8: R$/US$ 2022 | C8: 5.165 | D8: CONFERIR no SGS/Bacen (série 3698, média do ano) e citar.
B9: R$/US$ 2023 | C9: 4.995 | D9: CONFERIR no SGS/Bacen.
B10: R$/US$ 2024 | C10: 5.392 | D10: CONFERIR no SGS/Bacen.
B11: PODER CALORÍFICO DO GÁS
B12: PCI (kcal/m³) | C12: 8500 | D12: Base do modelo (LHV). Coerente com os fatores de emissão IPCC, que são NCV.
B13: PCS (kcal/m³) | C13: 9400 | D13: Base usada pelo Boletim do Gás. Verificado por reconstrução: 3,812 R$/m³ ÷ 6,097 = 16,761 US$/MMBtu exige PCS 9.400.
B14: kcal -> GJ | C14: 4.1868e-06 | D14: Constante. 1 kcal = 4,1868 J.
B15: PCI em GJ/m³ | C15: =C12*C14 -> 0.0355878 | D15: Calculado.
B16: FAIXA DE CONSUMO DO GÁS
B17: Faixa para ancorar o nível | C17: 50000 | D17: Digite 20000 ou 50000. Recomendado 50000: maior faixa publicada, mais próxima do porte siderúrgico.
B18: TRIBUTOS
B19: Convenção | C19: COM | D19: Digite SEM ou COM. Deve ser a mesma para eletricidade e gás. Escolhido: COM. A planta desembolsa o tributo; excluir subdimensiona o custo. Nota: ICMS sobre insumo industrial e parcialmente creditavel, logo COM superestima o custo liquido — vies conservador deliberado.
B20: OUTROS
B21: MWh -> GJ | C21: 3.6 | D21: Constante.
B22: DERIVADOS (não editar)
B23: Câmbio do ano-base | C23: =IF(C6=2022,C8,IF(C6=2023,C9,IF(C6=2024,C10,AVERAGE(C8:C10)))) -> 5.392 | D23: Se ano-base = 0, usa a média dos três anos.
B25: TRIBUTOS E DEMANDA — ELETRICIDADE
B26: ICMS padrão (%) | C26: 0.18 | D26: PREENCHER. Alíquota modal do estado sobre energia elétrica. Pode ser sobrescrita por UF na aba EE_por_UF. Fonte: CONFAZ / legislação estadual.
B27: PIS/Cofins (%) | C27: 0.05 | D27: PREENCHER. Alíquota efetiva sobre a tarifa; varia mês a mês no regime não-cumulativo. Confirmar.
B28: Incluir parcela de demanda? | C28: SIM | D28: SIM ou NAO. A TUSD de demanda (R$/kW) não está no preço em R$/MWh e é custo real da planta.
B29: Fator de carga | C29: 0.9 | D29: Usado para converter R$/kW em R$/MWh. Siderúrgica opera em base; 0,90 é premissa.
B31: Gross-up: tarifa com tributos = tarifa sem / (1 - ICMS - PIS/Cofins). Cálculo "por dentro", padrão brasileiro.
B33: CARVÃO METALÚRGICO IMPORTADO
B34: PCI carvão metalúrgico (kcal/kg) | C34: 7400 | D34: CONFERIR: fator de conversão do BEN/EPE para carvão metalúrgico importado
B35: PCI em GJ/t | C35: =C34*C14*1000 -> 30.98232
B36: Tributos sobre o CIF | C36: CIF puro | D36: II (TEC) = 0% p/ NCM 2701.12.00; ICMS-importação de insumo industrial em geral diferido (MG/ES/RJ/CE). Convenção COM atendida pelo CIF. Documentar se revisar.
B38: ÓLEO DIESEL
B39: Preço nacional no Model_Config (USD/GJ) | C39: 22 | D39: Nível da Fuel_Prices do Model_Config_12 (ancoragem do método da razão; ANP revenda só dá a estrutura relativa entre UFs)
B41: HIDROGÊNIO ELETROLÍTICO
B42: Preço nacional no Model_Config (USD/GJ) | C42: 41.6 | D42: Nível da Fuel_Prices do Model_Config_12
B43: Alfa: fração eletricidade no LCOH | C43: 0.72 | D43: Eletricidade responde por ~60-80% do LCOH eletrolítico (IEA Global Hydrogen Review; IRENA Green Hydrogen Cost Reduction). CITAR fonte específica e ano na tese.
B44: Razão amortecida: H2(UF) = nível x [alfa x EE(UF)/EE(nac) + (1-alfa)]. Só a parcela elétrica do custo varia com a UF; CAPEX do eletrolisador, água e O&M não.
B46: MINÉRIO DE FERRO E PELOTA (método delta)
B47: Intensidade minério — família BF/IBT (t/t aço) | C47: 1.6 | D47: BF-BOF MC/CC/CCS + IBT. Coeficiente técnico típico — CONFERIR e citar (worldsteel/IEA/refs do modelo)
B48: Intensidade pelota — família DR (t/t aço) | C48: 1.45 | D48: DR-NG e DR-H2, pelota DR-grade (Fe>67%). CONFERIR e citar
...

Sheet EE_ANEEL
A1: Eletricidade — ANEEL, tarifas homologadas (Subgrupo A4, Verde, Tarifa de Aplicação, Fora ponta, MWh)
A2: Valores vigentes em 31/12 de cada ano, em R$/MWh. Preço = TUSD + TE (sem tributos). Colunas amarelas: você edita. UF "VERIFICAR" = não identifiquei a distribuidora com segurança.
A4: Distribuidora (SigAgente) | B4: UF | C4: Peso | D4: Tipo | E4: TUSD 2022 | F4: TE 2022 | G4: Total 2022 | H4: TUSD 2023 | I4: TE 2023 | J4: Total 2023 | K4: TUSD 2024 | L4: TE 2024 | M4: Total 2024 | N4: Total ano-base | O4: TUSD demanda 2024 (R$/kW)
A5: CASTRO-DIS | B5: PR | C5: 0 | D5: Menor porte | E5: 84.56 | F5: 201.63 | G5: =E5+F5 -> 286.19 | H5: 90.49 | I5: 233.17 | J5: =H5+I5 -> 323.66 | K5: 95.2 | L5: 274.63 | M5: =K5+L5 -> 369.83 | N5: =IF(Premissas!$C$6=2022,G5,IF(Premissas!$C$6=2023,J5,IF(Premissas!$C$6=2024,M5,AVERAGE(G5,J5,M5)))) -> 369.83 | O5: 27.79
A6: CEA | B6: AP | C6: 1 | D6: Concessionária | E6: 181.48 | F6: 215.6 | G6: =E6+F6 -> 397.08 | H6: 181.48 | I6: 215.6 | J6: =H6+I6 -> 397.08 | K6: 193.63 | L6: 193.81 | M6: =K6+L6 -> 387.44 | N6: =IF(Premissas!$C$6=2022,G6,IF(Premissas!$C$6=2023,J6,IF(Premissas!$C$6=2024,M6,AVERAGE(G6,J6,M6)))) -> 387.44 | O6: 33.76
A7: CEDRAP | B7: VERIFICAR | C7: 0 | D7: Cooperativa/Perm. | E7: 98.98 | F7: 266.47 | G7: =E7+F7 -> 365.45 | H7: 84.74 | I7: 280.82 | J7: =H7+I7 -> 365.56 | K7: 95.85 | L7: 200.37 | M7: =K7+L7 -> 296.22 | N7: =IF(Premissas!$C$6=2022,G7,IF(Premissas!$C$6=2023,J7,IF(Premissas!$C$6=2024,M7,AVERAGE(G7,J7,M7)))) -> 296.22 | O7: 37.77
A8: CEDRI | B8: VERIFICAR | C8: 0 | D8: Cooperativa/Perm. | E8: 126.58 | F8: 269.21 | G8: =E8+F8 -> 395.79 | H8: 97.29 | I8: 429.57 | J8: =H8+I8 -> 526.86 | K8: 97.9 | L8: 318.75 | M8: =K8+L8 -> 416.65 | N8: =IF(Premissas!$C$6=2022,G8,IF(Premissas!$C$6=2023,J8,IF(Premissas!$C$6=2024,M8,AVERAGE(G8,J8,M8)))) -> 416.65 | O8: 35.7
A9: CEEE-D | B9: RS | C9: 1 | D9: Concessionária | E9: 137.58 | F9: 266.09 | G9: =E9+F9 -> 403.67 | H9: 94.16 | I9: 264.74 | J9: =H9+I9 -> 358.9 | K9: 124.73 | L9: 239.05 | M9: =K9+L9 -> 363.78 | N9: =IF(Premissas!$C$6=2022,G9,IF(Premissas!$C$6=2023,J9,IF(Premissas!$C$6=2024,M9,AVERAGE(G9,J9,M9)))) -> 363.78 | O9: 31.81
A10: CEGERO | B10: VERIFICAR | C10: 0 | D10: Cooperativa/Perm. | E10: 105.41 | F10: 194.01 | G10: =E10+F10 -> 299.42 | H10: 109.7 | I10: 200.1 | J10: =H10+I10 -> 309.8 | K10: 100.87 | L10: 222 | M10: =K10+L10 -> 322.87 | N10: =IF(Premissas!$C$6=2022,G10,IF(Premissas!$C$6=2023,J10,IF(Premissas!$C$6=2024,M10,AVERAGE(G10,J10,M10)))) -> 322.87 | O10: 16.59
A11: CEJAMA | B11: VERIFICAR | C11: 0 | D11: Cooperativa/Perm. | E11: 88.7 | F11: 191.01 | G11: =E11+F11 -> 279.71 | H11: 82.41 | I11: 192.22 | J11: =H11+I11 -> 274.63 | K11: 94.71 | L11: 212.61 | M11: =K11+L11 -> 307.32 | N11: =IF(Premissas!$C$6=2022,G11,IF(Premissas!$C$6=2023,J11,IF(Premissas!$C$6=2024,M11,AVERAGE(G11,J11,M11)))) -> 307.32 | O11: 35.83
A12: CELESC | B12: SC | C12: 1 | D12: Concessionária | E12: 126.25 | F12: 250.04 | G12: =E12+F12 -> 376.29 | H12: 100.39 | I12: 277.93 | J12: =H12+I12 -> 378.32 | K12: 106.86 | L12: 286.47 | M12: =K12+L12 -> 393.33 | N12: =IF(Premissas!$C$6=2022,G12,IF(Premissas!$C$6=2023,J12,IF(Premissas!$C$6=2024,M12,AVERAGE(G12,J12,M12)))) -> 393.33 | O12: 17.71
A13: CELETRO | B13: VERIFICAR | C13: 0 | D13: Cooperativa/Perm. | E13: 102.72 | F13: 251.92 | G13: =E13+F13 -> 354.64 | H13: 115.75 | I13: 328.49 | J13: =H13+I13 -> 444.24 | K13: 133.46 | L13: 321.48 | M13: =K13+L13 -> 454.94 | N13: =IF(Premissas!$C$6=2022,G13,IF(Premissas!$C$6=2023,J13,IF(Premissas!$C$6=2024,M13,AVERAGE(G13,J13,M13)))) -> 454.94 | O13: 40.51
A14: CEMIG-D | B14: MG | C14: 1 | D14: Concessionária | E14: 117.81 | F14: 231.69 | G14: =E14+F14 -> 349.5 | H14: 115.3 | I14: 298.38 | J14: =H14+I14 -> 413.68 | K14: 122.95 | L14: 297.69 | M14: =K14+L14 -> 420.64 | N14: =IF(Premissas!$C$6=2022,G14,IF(Premissas!$C$6=2023,J14,IF(Premissas!$C$6=2024,M14,AVERAGE(G14,J14,M14)))) -> 420.64 | O14: 22.23
A15: CEMIRIM | B15: VERIFICAR | C15: 0 | D15: Cooperativa/Perm. | E15: 100.35 | F15: 210.64 | G15: =E15+F15 -> 310.99 | H15: 101.9 | I15: 177.61 | J15: =H15+I15 -> 279.51 | K15: 99.25 | L15: 222.84 | M15: =K15+L15 -> 322.09 | N15: =IF(Premissas!$C$6=2022,G15,IF(Premissas!$C$6=2023,J15,IF(Premissas!$C$6=2024,M15,AVERAGE(G15,J15,M15)))) -> 322.09 | O15: 27.69
A16: CEPRAG | B16: VERIFICAR | C16: 0 | D16: Cooperativa/Perm. | E16: 104.84 | F16: 202.43 | G16: =E16+F16 -> 307.27 | H16: 87.83 | I16: 189.02 | J16: =H16+I16 -> 276.85 | K16: 100.63 | L16: 190.57 | M16: =K16+L16 -> 291.2 | N16: =IF(Premissas!$C$6=2022,G16,IF(Premissas!$C$6=2023,J16,IF(Premissas!$C$6=2024,M16,AVERAGE(G16,J16,M16)))) -> 291.2 | O16: 33.28
... A107: Âmbar Amazonas | B107: AM | C107: 1 | D107: Concessionária | E107: 182.53 | F107: 272.76 | G107: =E107+F107 -> 455.29 | H107: 182.53 | I107: 272.76 | J107: =H107+I107 -> 455.29 | K107: 143.78 | L107: 369.8 | M107: =K107+L107 -> 513.58 | N107: =IF(Premissas!$C$6=2022,G107,IF(Premissas!$C$6=2023,J107,IF(Premissas!$C$6=2024,M107,AVERAGE(G107,J107,M107)))) -> 513.58 | O107: 24.15

Sheet EE_por_UF
A1: Eletricidade por UF
A2: Média das distribuidoras com Peso = 1 em EE_ANEEL. Coluna G (ICMS) é amarela: sobrescreva por UF. UF sem nenhuma distribuidora marcada herda a média nacional.
A4: UF | B4: N distrib. (peso 1) | C4: TUSD+TE fora ponta (R$/MWh) | D4: TUSD demanda (R$/kW) | E4: Adicional de demanda (R$/MWh) | F4: Subtotal sem tributos (R$/MWh) | G4: ICMS (%) | H4: Total conforme convenção (R$/MWh) | I4: R$/GJ | J4: USD/GJ | K4: Usa fallback nacional?
A5: AC | B5: =SUMIFS(EE_ANEEL!$C$5:$C$107,EE_ANEEL!$B$5:$B$107,A5) -> 1 | C5: =IF(B5=0,$C$33,SUMPRODUCT((EE_ANEEL!$B$5:$B$107=A5)*EE_ANEEL!$C$5:$C$107*EE_ANEEL!$N$5:$N$107)/B5) -> 316.88 | D5: =IF(B5=0,$D$33,SUMPRODUCT((EE_ANEEL!$B$5:$B$107=A5)*EE_ANEEL!$C$5:$C$107*EE_ANEEL!$O$5:$O$107)/B5) -> 31.74 | E5: =IF(Premissas!$C$28="SIM",D5*12/(8.76*Premissas!$C$29),0) -> 48.310502 | F5: =C5+E5 -> 365.1905 | G5: =Premissas!$C$26 -> 0.18 | H5: =IF(Premissas!$C$19="COM",F5/(1-G5-Premissas!$C$27),F5) -> 474.27338 | I5: =H5/Premissas!$C$21 -> 131.74261 | J5: =I5/Premissas!$C$23 -> 24.432976 | K5: =IF(B5=0,"SIM — nacional","")
A6: AL | B6: =SUMIFS(EE_ANEEL!$C$5:$C$107,EE_ANEEL!$B$5:$B$107,A6) -> 1 | C6: =IF(B6=0,$C$33,SUMPRODUCT((EE_ANEEL!$B$5:$B$107=A6)*EE_ANEEL!$C$5:$C$107*EE_ANEEL!$N$5:$N$107)/B6) -> 420.46 | D6: =IF(B6=0,$D$33,SUMPRODUCT((EE_ANEEL!$B$5:$B$107=A6)*EE_ANEEL!$C$5:$C$107*EE_ANEEL!$O$5:$O$107)/B6) -> 27.48 | E6: =IF(Premissas!$C$28="SIM",D6*12/(8.76*Premissas!$C$29),0) -> 41.826484 | F6: =C6+E6 -> 462.28648 | G6: =Premissas!$C$26 -> 0.18 | H6: =IF(Premissas!$C$19="COM",F6/(1-G6-Premissas!$C$27),F6) -> 600.37206 | I6: =H6/Premissas!$C$21 -> 166.77002 | J6: =I6/Premissas!$C$23 -> 30.929157 | K6: =IF(B6=0,"SIM — nacional","")
A7: AM | B7: =SUMIFS(EE_ANEEL!$C$5:$C$107,EE_ANEEL!$B$5:$B$107,A7) -> 1 | C7: =IF(B7=0,$C$33,SUMPRODUCT((EE_ANEEL!$B$5:$B$107=A7)*EE_ANEEL!$C$5:$C$107*EE_ANEEL!$N$5:$N$107)/B7) -> 513.58 | D7: =IF(B7=0,$D$33,SUMPRODUCT((EE_ANEEL!$B$5:$B$107=A7)*EE_ANEEL!$C$5:$C$107*EE_ANEEL!$O$5:$O$107)/B7) -> 24.15 | E7: =IF(Premissas!$C$28="SIM",D7*12/(8.76*Premissas!$C$29),0) -> 36.757991 | F7: =C7+E7 -> 550.33799 | G7: =Premissas!$C$26 -> 0.18 | H7: =IF(Premissas!$C$19="COM",F7/(1-G7-Premissas!$C$27),F7) -> 714.72466 | I7: =H7/Premissas!$C$21 -> 198.53463 | J7: =I7/Premissas!$C$23 -> 36.82022 | K7: =IF(B7=0,"SIM — nacional","")
A8: AP | B8: =SUMIFS(EE_ANEEL!$C$5:$C$107,EE_ANEEL!$B$5:$B$107,A8) -> 1 | C8: =IF(B8=0,$C$33,SUMPRODUCT((EE_ANEEL!$B$5:$B$107=A8)*EE_ANEEL!$C$5:$C$107*EE_ANEEL!$N$5:$N$107)/B8) -> 387.44 | D8: =IF(B8=0,$D$33,SUMPRODUCT((EE_ANEEL!$B$5:$B$107=A8)*EE_ANEEL!$C$5:$C$107*EE_ANEEL!$O$5:$O$107)/B8) -> 33.76 | E8: =IF(Premissas!$C$28="SIM",D8*12/(8.76*Premissas!$C$29),0) -> 51.385084 | F8: =C8+E8 -> 438.82508 | G8: =Premissas!$C$26 -> 0.18 | H8: =IF(Premissas!$C$19="COM",F8/(1-G8-Premissas!$C$27),F8) -> 569.90271 | I8: =H8/Premissas!$C$21 -> 158.30631 | J8: =I8/Premissas!$C$23 -> 29.359478 | K8: =IF(B8=0,"SIM — nacional","")
A9: BA | B9: =SUMIFS(EE_ANEEL!$C$5:$C$107,EE_ANEEL!$B$5:$B$107,A9) -> 1 | C9: =IF(B9=0,$C$33,SUMPRODUCT((EE_ANEEL!$B$5:$B$107=A9)*EE_ANEEL!$C$5:$C$107*EE_ANEEL!$N$5:$N$107)/B9) -> 362.7 | D9: =IF(B9=0,$D$33,SUMPRODUCT((EE_ANEEL!$B$5:$B$107=A9)*EE_ANEEL!$C$5:$C$107*EE_ANEEL!$O$5:$O$107)/B9) -> 38.84 | E9: =IF(Premissas!$C$28="SIM",D9*12/(8.76*Premissas!$C$29),0) -> 59.117199 | F9: =C9+E9 -> 421.8172 | G9: =Premissas!$C$26 -> 0.18 | H9: =IF(Premissas!$C$19="COM",F9/(1-G9-Premissas!$C$27),F9) -> 547.81454 | I9: =H9/Premissas!$C$21 -> 152.17071 | J9: =I9/Premissas!$C$23 -> 28.22157 | K9: =IF(B9=0,"SIM — nacional","")
A10: CE | B10: =SUMIFS(EE_ANEEL!$C$5:$C$107,EE_ANEEL!$B$5:$B$107,A10) -> 1 | C10: =IF(B10=0,$C$33,SUMPRODUCT((EE_ANEEL!$B$5:$B$107=A10)*EE_ANEEL!$C$5:$C$107*EE_ANEEL!$N$5:$N$107)/B10) -> 340.99 | D10: =IF(B10=0,$D$33,SUMPRODUCT((EE_ANEEL!$B$5:$B$107=A10)*EE_ANEEL!$C$5:$C$107*EE_ANEEL!$O$5:$O$107)/B10) -> 22.65 | E10: =IF(Premissas!$C$28="SIM",D10*12/(8.76*Premissas!$C$29),0) -> 34.474886 | F10: =C10+E10 -> 375.46489 | G10: =Premissas!$C$26 -> 0.18 | H10: =IF(Premissas!$C$19="COM",F10/(1-G10-Premissas!$C$27),F10) -> 487.61673 | I10: =H10/Premissas!$C$21 -> 135.44909 | J10: =I10/Premissas!$C$23 -> 25.120381 | K10: =IF(B10=0,"SIM — nacional","")
A11: DF | B11: =SUMIFS(EE_ANEEL!$C$5:$C$107,EE_ANEEL!$B$5:$B$107,A11) -> 1 | C11: =IF(B11=0,$C$33,SUMPRODUCT((EE_ANEEL!$B$5:$B$107=A11)*EE_ANEEL!$C$5:$C$107*EE_ANEEL!$N$5:$N$107)/B11) -> 492.7 | D11: =IF(B11=0,$D$33,SUMPRODUCT((EE_ANEEL!$B$5:$B$107=A11)*EE_ANEEL!$C$5:$C$107*EE_ANEEL!$O$5:$O$107)/B11) -> 12.3 | E11: =IF(Premissas!$C$28="SIM",D11*12/(8.76*Premissas!$C$29),0) -> 18.721461 | F11: =C11+E11 -> 511.42146 | G11: =Premissas!$C$26 -> 0.18 | H11: =IF(Premissas!$C$19="COM",F11/(1-G11-Premissas!$C$27),F11) -> 664.18372 | I11: =H11/Premissas!$C$21 -> 184.49548 | J11: =I11/Premissas!$C$23 -> 34.21652 | K11: =IF(B11=0,"SIM — nacional","")
A12: ES | B12: =SUMIFS(EE_ANEEL!$C$5:$C$107,EE_ANEEL!$B$5:$B$107,A12) -> 1 | C12: =IF(B12=0,$C$33,SUMPRODUCT((EE_ANEEL!$B$5:$B$107=A12)*EE_ANEEL!$C$5:$C$107*EE_ANEEL!$N$5:$N$107)/B12) -> 392.61 | D12: =IF(B12=0,$D$33,SUMPRODUCT((EE_ANEEL!$B$5:$B$107=A12)*EE_ANEEL!$C$5:$C$107*EE_ANEEL!$O$5:$O$107)/B12) -> 31.83 | E12: =IF(Premissas!$C$28="SIM",D12*12/(8.76*Premissas!$C$29),0) -> 48.447489 | F12: =C12+E12 -> 441.05749 | G12: =Premissas!$C$26 -> 0.18 | H12: =IF(Premissas!$C$19="COM",F12/(1-G12-Premissas!$C$27),F12) -> 572.80193 | I12: =H12/Premissas!$C$21 -> 159.11165 | J12: =I12/Premissas!$C$23 -> 29.508837 | K12: =IF(B12=0,"SIM — nacional","")
A13: GO | B13: =SUMIFS(EE_ANEEL!$C$5:$C$107,EE_ANEEL!$B$5:$B$107,A13) -> 1 | C13: =IF(B13=0,$C$33,SUMPRODUCT((EE_ANEEL!$B$5:$B$107=A13)*EE_ANEEL!$C$5:$C$107*EE_ANEEL!$N$5:$N$107)/B13) -> 354.23 | D13: =IF(B13=0,$D$33,SUMPRODUCT((EE_ANEEL!$B$5:$B$107=A13)*EE_ANEEL!$C$5:$C$107*EE_ANEEL!$O$5:$O$107)/B13) -> 27.09 | E13: =IF(Premissas!$C$28="SIM",D13*12/(8.76*Premissas!$C$29),0) -> 41.232877 | F13: =C13+E13 -> 395.46288 | G13: =Premissas!$C$26 -> 0.18 | H13: =IF(Premissas!$C$19="COM",F13/(1-G13-Premissas!$C$27),F13) -> 513.58815 | I13: =H13/Premissas!$C$21 -> 142.66338 | J13: =I13/Premissas!$C$23 -> 26.458341 | K13: =IF(B13=0,"SIM — nacional","")
A14: MA | B14: =SUMIFS(EE_ANEEL!$C$5:$C$107,EE_ANEEL!$B$5:$B$107,A14) -> 1 | C14: =IF(B14=0,$C$33,SUMPRODUCT((EE_ANEEL!$B$5:$B$107=A14)*EE_ANEEL!$C$5:$C$107*EE_ANEEL!$N$5:$N$107)/B14) -> 315.73 | D14: =IF(B14=0,$D$33,SUMPRODUCT((EE_ANEEL!$B$5:$B$107=A14)*EE_ANEEL!$C$5:$C$107*EE_ANEEL!$O$5:$O$107)/B14) -> 28.45 | E14: =IF(Premissas!$C$28="SIM",D14*12/(8.76*Premissas!$C$29),0) -> 43.302892 | F14: =C14+E14 -> 359.03289 | G14: =Premissas!$C$26 -> 0.18 | H14: =IF(Premissas!$C$19="COM",F14/(1-G14-Premissas!$C$27),F14) -> 466.27648 | I14: =H14/Premissas!$C$21 -> 129.52125 | J14: =I14/Premissas!$C$23 -> 24.021002 | K14: =IF(B14=0,"SIM — nacional","")
A15: MG | B15: =SUMIFS(EE_ANEEL!$C$5:$C$107,EE_ANEEL!$B$5:$B$107,A15) -> 1 | C15: =IF(B15=0,$C$33,SUMPRODUCT((EE_ANEEL!$B$5:$B$107=A15)*EE_ANEEL!$C$5:$C$107*EE_ANEEL!$N$5:$N$107)/B15) -> 420.64 | D15: =IF(B15=0,$D$33,SUMPRODUCT((EE_ANEEL!$B$5:$B$107=A15)*EE_ANEEL!$C$5:$C$107*EE_ANEEL!$O$5:$O$107)/B15) -> 22.23 | E15: =IF(Premissas!$C$28="SIM",D15*12/(8.76*Premissas!$C$29),0) -> 33.835616 | F15: =C15+E15 -> 454.47562 | G15: =Premissas!$C$26 -> 0.18 | H15: =IF(Premissas!$C$19="COM",F15/(1-G15-Premissas!$C$27),F15) -> 590.22807 | I15: =H15/Premissas!$C$21 -> 163.95224 | J15: =I15/Premissas!$C$23 -> 30.406573 | K15: =IF(B15=0,"SIM — nacional","")
A16: MS | B16: =SUMIFS(EE_ANEEL!$C$5:$C$107,EE_ANEEL!$B$5:$B$107,A16) -> 1 | C16: =IF(B16=0,$C$33,SUMPRODUCT((EE_ANEEL!$B$5:$B$107=A16)*EE_ANEEL!$C$5:$C$107*EE_ANEEL!$N$5:$N$107)/B16) -> 422.1 | D16: =IF(B16=0,$D$33,SUMPRODUCT((EE_ANEEL!$B$5:$B$107=A16)*EE_ANEEL!$C$5:$C$107*EE_ANEEL!$O$5:$O$107)/B16) -> 34.28 | E16: =IF(Premissas!$C$28="SIM",D16*12/(8.76*Premissas!$C$29),0) -> 52.17656 | F16: =C16+E16 -> 474.27656 | G16: =Premissas!$C$26 -> 0.18 | H16: =IF(Premissas!$C$19="COM",F16/(1-G16-Premissas!$C$27),F16) -> 615.94358 | I16: =H16/Premissas!$C$21 -> 171.09544 | J16: =I16/Premissas!$C$23 -> 31.73135 | K16: =IF(B16=0,"SIM — nacional","")
... A31: TO | B31: =SUMIFS(EE_ANEEL!$C$5:$C$107,EE_ANEEL!$B$5:$B$107,A31) -> 1 | C31: =IF(B31=0,$C$33,SUMPRODUCT((EE_ANEEL!$B$5:$B$107=A31)*EE_ANEEL!$C$5:$C$107*EE_ANEEL!$N$5:$N$107)/B31) -> 325.15 | D31: =IF(B31=0,$D$33,SUMPRODUCT((EE_ANEEL!$B$5:$B$107=A31)*EE_ANEEL!$C$5:$C$107*EE_ANEEL!$O$5:$O$107)/B31) -> 46.35 | E31: =IF(Premissas!$C$28="SIM",D31*12/(8.76*Premissas!$C$29),0) -> 70.547945 | F31: =C31+E31 -> 395.69795 | G31: =Premissas!$C$26 -> 0.18 | H31: =IF(Premissas!$C$19="COM",F31/(1-G31-Premissas!$C$27),F31) -> 513.89344 | I31: =H31/Premissas!$C$21 -> 142.74818 | J31: =I31/Premissas!$C$23 -> 26.474068 | K31: =IF(B31=0,"SIM — nacional","")
B33: Média nacional | C33: =SUMPRODUCT(EE_ANEEL!$C$5:$C$107,EE_ANEEL!$N$5:$N$107)/SUM(EE_ANEEL!$C$5:$C$107) -> 385.36909 | D33: =SUMPRODUCT(EE_ANEEL!$C$5:$C$107,EE_ANEEL!$O$5:$O$107)/SUM(EE_ANEEL!$C$5:$C$107) -> 27.093636

Sheet GN_Boletim
A1: Gás natural — Boletim Mensal do Gás (MME), segmento industrial 20.000 m³/dia, US$/MMBtu, COM tributos
A2: Valores lidos dos gráficos "Preço do Gás Natural ao Consumidor Final - Por Distribuidora" de cada edição. São observações de DEZEMBRO (set/2025 na última coluna), não médias anuais. Servem apenas para a ESTRUTURA relativa.
A4: Distribuidora | B4: UF | C4: Região | D4: dez/2022 | E4: dez/2023 | F4: dez/2024 | G4: set/2025 | H4: Obs ano-base | I4: Razão vs nacional
A5: Algás | B5: AL | C5: Nordeste | D5: 18.9 | E5: 16.9 | F5: 15.8 | G5: 16 | H5: =IF(Premissas!$C$6=2022,D5,IF(Premissas!$C$6=2023,E5,IF(Premissas!$C$6=2024,F5,AVERAGE(D5:F5)))) -> 15.8 | I5: =H5/$C$29 -> 0.94272076
A6: Bahiagás | B6: BA | C6: Nordeste | D6: 18.2 | E6: 17 | F6: 13.3 | G6: 15.7 | H6: =IF(Premissas!$C$6=2022,D6,IF(Premissas!$C$6=2023,E6,IF(Premissas!$C$6=2024,F6,AVERAGE(D6:F6)))) -> 13.3 | I6: =H6/$C$29 -> 0.79355609
A7: ES GÁS | B7: ES | C7: Sudeste | D7: 21.7 | E7: 21.8 | F7: 16.6 | G7: 18.8 | H7: =IF(Premissas!$C$6=2022,D7,IF(Premissas!$C$6=2023,E7,IF(Premissas!$C$6=2024,F7,AVERAGE(D7:F7)))) -> 16.6 | I7: =H7/$C$29 -> 0.99045346
A8: Ceg | B8: RJ | C8: Sudeste | D8: 22.2 | E8: 21.8 | F8: 18.7 | G8: 20.7 | H8: =IF(Premissas!$C$6=2022,D8,IF(Premissas!$C$6=2023,E8,IF(Premissas!$C$6=2024,F8,AVERAGE(D8:F8)))) -> 18.7 | I8: =H8/$C$29 -> 1.1157518
A9: Ceg Rio | B9: RJ | C9: Sudeste | D9: 21.1 | E9: 19.8 | F9: 17.5 | G9: 19.3 | H9: =IF(Premissas!$C$6=2022,D9,IF(Premissas!$C$6=2023,E9,IF(Premissas!$C$6=2024,F9,AVERAGE(D9:F9)))) -> 17.5 | I9: =H9/$C$29 -> 1.0441527
A10: Cegás | B10: CE | C10: Nordeste | D10: 23.4 | E10: 23.8 | F10: 18.7 | G10: 19.9 | H10: =IF(Premissas!$C$6=2022,D10,IF(Premissas!$C$6=2023,E10,IF(Premissas!$C$6=2024,F10,AVERAGE(D10:F10)))) -> 18.7 | I10: =H10/$C$29 -> 1.1157518
A11: Comgás | B11: SP | C11: Sudeste | D11: 25 | E11: 20.1 | F11: 17.7 | G11: 17.9 | H11: =IF(Premissas!$C$6=2022,D11,IF(Premissas!$C$6=2023,E11,IF(Premissas!$C$6=2024,F11,AVERAGE(D11:F11)))) -> 17.7 | I11: =H11/$C$29 -> 1.0560859
A12: Copergás | B12: PE | C12: Nordeste | D12: 18.9 | E12: 18.1 | F12: 16.5 | G12: 17.4 | H12: =IF(Premissas!$C$6=2022,D12,IF(Premissas!$C$6=2023,E12,IF(Premissas!$C$6=2024,F12,AVERAGE(D12:F12)))) -> 16.5 | I12: =H12/$C$29 -> 0.98448687
A13: Pbgás | B13: PB | C13: Nordeste | D13: 20.2 | E13: 19.5 | F13: 17.6 | G13: 19 | H13: =IF(Premissas!$C$6=2022,D13,IF(Premissas!$C$6=2023,E13,IF(Premissas!$C$6=2024,F13,AVERAGE(D13:F13)))) -> 17.6 | I13: =H13/$C$29 -> 1.0501193
A14: Potigás | B14: RN | C14: Nordeste | D14: 16.4 | E14: 18.6 | F14: 17.7 | G14: 21.2 | H14: =IF(Premissas!$C$6=2022,D14,IF(Premissas!$C$6=2023,E14,IF(Premissas!$C$6=2024,F14,AVERAGE(D14:F14)))) -> 17.7 | I14: =H14/$C$29 -> 1.0560859
A15: Sergás | B15: SE | C15: Nordeste | D15: 17.9 | E15: 19.3 | F15: 17.4 | G15: 18.7 | H15: =IF(Premissas!$C$6=2022,D15,IF(Premissas!$C$6=2023,E15,IF(Premissas!$C$6=2024,F15,AVERAGE(D15:F15)))) -> 17.4 | I15: =H15/$C$29 -> 1.0381862
A16: Gasmig | B16: MG | C16: Sudeste | D16: 24 | E16: 22.8 | F16: 15.5 | G16: 17.4 | H16: =IF(Premissas!$C$6=2022,D16,IF(Premissas!$C$6=2023,E16,IF(Premissas!$C$6=2024,F16,AVERAGE(D16:F16)))) -> 15.5 | I16: =H16/$C$29 -> 0.924821
... A23: Cigás | B23: AM | C23: Norte | D23: 13.7 | E23: 15.6 | F23: 14.1 | G23: 14.3 | H23: =IF(Premissas!$C$6=2022,D23,IF(Premissas!$C$6=2023,E23,IF(Premissas!$C$6=2024,F23,AVERAGE(D23:F23)))) -> 14.1 | I23: =H23/$C$29 -> 0.84128878
A26: VERIFICAÇÃO E ÂNCORAS NACIONAIS
A27: Média simples calculada (dez do ano-base) | C27: =AVERAGE(H5:H23) -> 16.773684
A28: Nacional publicado no Boletim, 20.000 m³/d, dez (US$/MMBtu) | D28: 20.98 | E28: 20.22 | F28: 16.76 | G28: 19.44
A29: Nacional do ano-base (denominador da razão) | C29: =IF(Premissas!$C$6=2022,D28,IF(Premissas!$C$6=2023,E28,IF(Premissas!$C$6=2024,F28,AVERAGE(D28:F28)))) -> 16.76
A30: Diferença calculado - publicado (deve ser ~0) | C30: =C27-C29 -> 0.013684211 | E30: Teste de leitura dos gráficos. Verificado: dez/22 20,99 vs 20,98 | dez/23 20,22 vs 20,22 | dez/24 16,77 vs 16,76 | set/25 19,45 vs 19,44.
A32: NÍVEL — média anual nacional publicada (R$/m³, com tributos)
A33: Faixa 20.000 m³/dia | D33: 3.97 | E33: 3.79 | F33: 3.75
A34: Faixa 50.000 m³/dia | D34: 3.91 | E34: 3.72 | F34: 3.67
A35: Média anual do ano-base, faixa escolhida (R$/m³) | C35: =IF(Premissas!$C$17=20000,IF(Premissas!$C$6=2022,D33,IF(Premissas!$C$6=2023,E33,IF(Premissas!$C$6=2024,F33,AVERAGE(D33:F33)))),IF(Premissas!$C$6=2022,D34,IF(Premissas!$C$6=2023,E34,IF(Premissas!$C$6=2024,F34,AVERAGE(D34:F34))))) -> 3.67 | E35: Fonte: Boletim do Gás, "Histórico de Preços - Segmento Industrial", linha Média Nacional (R$/m³).
A37: TRIBUTOS — participação de impostos no preço industrial 20.000 m³/d, por região
A38: Região | B38: Sem imposto | C38: Imposto | D38: % imposto
A39: Nordeste | B39: 65.64 | C39: 24.59 | D39: =C39/(B39+C39) -> 0.27252577
A40: Norte | B40: 56.37 | C40: 29.37 | D40: =C40/(B40+C40) -> 0.34254724
A41: Sudeste | B41: 78.7 | C41: 23.58 | D41: =C41/(B41+C41) -> 0.23054361
A42: Sul | B42: 80.14 | C42: 24.96 | D42: =C42/(B42+C42) -> 0.23748811
A43: Centro-Oeste | B43: 60.28 | C43: 33.18 | D43: =C43/(B43+C43) -> 0.35501819
A44: Fonte: Boletim do Gás dez/2024, "Competitividade do Gás Natural — preços ao consumidor final (R$/MMBTU)", gráfico "Gás industrial 20.000 m³/dia". Centro-Oeste não foi publicado em dez/2024; valor de set/2025.

Sheet GN_por_UF
A1: Gás natural por UF — método da razão
A2: Preço_UF = razão(estrutura de dezembro) × nível(média anual nacional). UF sem distribuidora com movimentação herda o nacional.
A4: UF | B4: Região | C4: Razão média das distribuidoras da UF | D4: R$/m³ (com tributos) | E4: R$/m³ (conforme convenção) | F4: USD/GJ base PCI | G4: Usa fallback nacional?
A5: AC | B5: Norte | C5: =IFERROR(AVERAGEIF(GN_Boletim!$B$5:$B$23,A5,GN_Boletim!$I$5:$I$23),1) -> 1 | D5: =C5*GN_Boletim!$C$35 -> 3.67 | E5: =IF(Premissas!$C$19="SEM",D5*(1-IFERROR(INDEX(GN_Boletim!$D$39:$D$43,MATCH(B5,GN_Boletim!$A$39:$A$43,0)),0)),D5) -> 3.67 | F5: =E5/Premissas!$C$23/Premissas!$C$15 -> 19.125599 | G5: =IF(COUNTIF(GN_Boletim!$B$5:$B$23,A5)=0,"SIM — nacional","") -> SIM — nacional
A6: AL | B6: Nordeste | C6: =IFERROR(AVERAGEIF(GN_Boletim!$B$5:$B$23,A6,GN_Boletim!$I$5:$I$23),1) -> 0.94272076 | D6: =C6*GN_Boletim!$C$35 -> 3.4597852 | E6: =IF(Premissas!$C$19="SEM",D6*(1-IFERROR(INDEX(GN_Boletim!$D$39:$D$43,MATCH(B6,GN_Boletim!$A$39:$A$43,0)),0)),D6) -> 3.4597852 | F6: =E6/Premissas!$C$23/Premissas!$C$15 -> 18.030099 | G6: =IF(COUNTIF(GN_Boletim!$B$5:$B$23,A6)=0,"SIM — nacional","")
A7: AM | B7: Norte | C7: =IFERROR(AVERAGEIF(GN_Boletim!$B$5:$B$23,A7,GN_Boletim!$I$5:$I$23),1) -> 0.84128878 | D7: =C7*GN_Boletim!$C$35 -> 3.0875298 | E7: =IF(Premissas!$C$19="SEM",D7*(1-IFERROR(INDEX(GN_Boletim!$D$39:$D$43,MATCH(B7,GN_Boletim!$A$39:$A$43,0)),0)),D7) -> 3.0875298 | F7: =E7/Premissas!$C$23/Premissas!$C$15 -> 16.090152 | G7: =IF(COUNTIF(GN_Boletim!$B$5:$B$23,A7)=0,"SIM — nacional","")
A8: AP | B8: Norte | C8: =IFERROR(AVERAGEIF(GN_Boletim!$B$5:$B$23,A8,GN_Boletim!$I$5:$I$23),1) -> 1 | D8: =C8*GN_Boletim!$C$35 -> 3.67 | E8: =IF(Premissas!$C$19="SEM",D8*(1-IFERROR(INDEX(GN_Boletim!$D$39:$D$43,MATCH(B8,GN_Boletim!$A$39:$A$43,0)),0)),D8) -> 3.67 | F8: =E8/Premissas!$C$23/Premissas!$C$15 -> 19.125599 | G8: =IF(COUNTIF(GN_Boletim!$B$5:$B$23,A8)=0,"SIM — nacional","") -> SIM — nacional
A9: BA | B9: Nordeste | C9: =IFERROR(AVERAGEIF(GN_Boletim!$B$5:$B$23,A9,GN_Boletim!$I$5:$I$23),1) -> 0.79355609 | D9: =C9*GN_Boletim!$C$35 -> 2.9123508 | E9: =IF(Premissas!$C$19="SEM",D9*(1-IFERROR(INDEX(GN_Boletim!$D$39:$D$43,MATCH(B9,GN_Boletim!$A$39:$A$43,0)),0)),D9) -> 2.9123508 | F9: =E9/Premissas!$C$23/Premissas!$C$15 -> 15.177235 | G9: =IF(COUNTIF(GN_Boletim!$B$5:$B$23,A9)=0,"SIM — nacional","")
A10: CE | B10: Nordeste | C10: =IFERROR(AVERAGEIF(GN_Boletim!$B$5:$B$23,A10,GN_Boletim!$I$5:$I$23),1) -> 1.1157518 | D10: =C10*GN_Boletim!$C$35 -> 4.0948091 | E10: =IF(Premissas!$C$19="SEM",D10*(1-IFERROR(INDEX(GN_Boletim!$D$39:$D$43,MATCH(B10,GN_Boletim!$A$39:$A$43,0)),0)),D10) -> 4.0948091 | F10: =E10/Premissas!$C$23/Premissas!$C$15 -> 21.339421 | G10: =IF(COUNTIF(GN_Boletim!$B$5:$B$23,A10)=0,"SIM — nacional","")
A11: DF | B11: Centro-Oeste | C11: =IFERROR(AVERAGEIF(GN_Boletim!$B$5:$B$23,A11,GN_Boletim!$I$5:$I$23),1) -> 1 | D11: =C11*GN_Boletim!$C$35 -> 3.67 | E11: =IF(Premissas!$C$19="SEM",D11*(1-IFERROR(INDEX(GN_Boletim!$D$39:$D$43,MATCH(B11,GN_Boletim!$A$39:$A$43,0)),0)),D11) -> 3.67 | F11: =E11/Premissas!$C$23/Premissas!$C$15 -> 19.125599 | G11: =IF(COUNTIF(GN_Boletim!$B$5:$B$23,A11)=0,"SIM — nacional","") -> SIM — nacional
A12: ES | B12: Sudeste | C12: =IFERROR(AVERAGEIF(GN_Boletim!$B$5:$B$23,A12,GN_Boletim!$I$5:$I$23),1) -> 0.99045346 | D12: =C12*GN_Boletim!$C$35 -> 3.6349642 | E12: =IF(Premissas!$C$19="SEM",D12*(1-IFERROR(INDEX(GN_Boletim!$D$39:$D$43,MATCH(B12,GN_Boletim!$A$39:$A$43,0)),0)),D12) -> 3.6349642 | F12: =E12/Premissas!$C$23/Premissas!$C$15 -> 18.943015 | G12: =IF(COUNTIF(GN_Boletim!$B$5:$B$23,A12)=0,"SIM — nacional","")
A13: GO | B13: Centro-Oeste | C13: =IFERROR(AVERAGEIF(GN_Boletim!$B$5:$B$23,A13,GN_Boletim!$I$5:$I$23),1) -> 1 | D13: =C13*GN_Boletim!$C$35 -> 3.67 | E13: =IF(Premissas!$C$19="SEM",D13*(1-IFERROR(INDEX(GN_Boletim!$D$39:$D$43,MATCH(B13,GN_Boletim!$A$39:$A$43,0)),0)),D13) -> 3.67 | F13: =E13/Premissas!$C$23/Premissas!$C$15 -> 19.125599 | G13: =IF(COUNTIF(GN_Boletim!$B$5:$B$23,A13)=0,"SIM — nacional","") -> SIM — nacional
A14: MA | B14: Nordeste | C14: =IFERROR(AVERAGEIF(GN_Boletim!$B$5:$B$23,A14,GN_Boletim!$I$5:$I$23),1) -> 1 | D14: =C14*GN_Boletim!$C$35 -> 3.67 | E14: =IF(Premissas!$C$19="SEM",D14*(1-IFERROR(INDEX(GN_Boletim!$D$39:$D$43,MATCH(B14,GN_Boletim!$A$39:$A$43,0)),0)),D14) -> 3.67 | F14: =E14/Premissas!$C$23/Premissas!$C$15 -> 19.125599 | G14: =IF(COUNTIF(GN_Boletim!$B$5:$B$23,A14)=0,"SIM — nacional","") -> SIM — nacional
A15: MG | B15: Sudeste | C15: =IFERROR(AVERAGEIF(GN_Boletim!$B$5:$B$23,A15,GN_Boletim!$I$5:$I$23),1) -> 0.924821 | D15: =C15*GN_Boletim!$C$35 -> 3.3940931 | E15: =IF(Premissas!$C$19="SEM",D15*(1-IFERROR(INDEX(GN_Boletim!$D$39:$D$43,MATCH(B15,GN_Boletim!$A$39:$A$43,0)),0)),D15) -> 3.3940931 | F15: =E15/Premissas!$C$23/Premissas!$C$15 -> 17.687755 | G15: =IF(COUNTIF(GN_Boletim!$B$5:$B$23,A15)=0,"SIM — nacional","")
A16: MS | B16: Centro-Oeste | C16: =IFERROR(AVERAGEIF(GN_Boletim!$B$5:$B$23,A16,GN_Boletim!$I$5:$I$23),1) -> 0.99642005 | D16: =C16*GN_Boletim!$C$35 -> 3.6568616 | E16: =IF(Premissas!$C$19="SEM",D16*(1-IFERROR(INDEX(GN_Boletim!$D$39:$D$43,MATCH(B16,GN_Boletim!$A$39:$A$43,0)),0)),D16) -> 3.6568616 | F16: =E16/Premissas!$C$23/Premissas!$C$15 -> 19.05713 | G16: =IF(COUNTIF(GN_Boletim!$B$5:$B$23,A16)=0,"SIM — nacional","")
... A31: TO | B31: Norte | C31: =IFERROR(AVERAGEIF(GN_Boletim!$B$5:$B$23,A31,GN_Boletim!$I$5:$I$23),1) -> 1 | D31: =C31*GN_Boletim!$C$35 -> 3.67 | E31: =IF(Premissas!$C$19="SEM",D31*(1-IFERROR(INDEX(GN_Boletim!$D$39:$D$43,MATCH(B31,GN_Boletim!$A$39:$A$43,0)),0)),D31) -> 3.67 | F31: =E31/Premissas!$C$23/Premissas!$C$15 -> 19.125599 | G31: =IF(COUNTIF(GN_Boletim!$B$5:$B$23,A31)=0,"SIM — nacional","") -> SIM — nacional

Sheet CM_Comex
A1: Carvão metalúrgico importado — Comex Stat (MDIC), NCM 2701.12.00, Brasil
A2: Hulha betuminosa, não aglomerada. Importações nacionais, consulta geral. CIF = FOB + frete + seguro, sem tributos internos (ver Premissas!B36). Fonte: comexstat.mdic.gov.br, extração 16/07/2026. CIF por porto/UF não diferenciado: carvão transoceânico é commodity global; a diferenciação estadual vem do frete interno (CM_Frete).
A4: Ano | B4: US$ CIF | C4: kg líquido | D4: CIF US$/t | E4: US$ FOB | F4: FOB US$/t
A5: 2022 | B5: 5379476170 | C5: 16521372159 | D5: =B5/C5*1000 -> 325.60711 | E5: 4983280595 | F5: =E5/C5*1000 -> 301.62631
A6: 2023 | B6: 3882374416 | C6: 16001240871 | D6: =B6/C6*1000 -> 242.62958 | E6: 3629414374 | F6: =E6/C6*1000 -> 226.82081
A7: 2024 | B7: 3088863498 | C7: 15588893168 | D7: =B7/C7*1000 -> 198.14515 | E7: 2837482343 | F7: =E7/C7*1000 -> 182.01949
A9: CIF do ano-base (US$/t) | D9: =IF(Premissas!C6=0,AVERAGE(D5:D7),INDEX(D5:D7,MATCH(Premissas!C6,A5:A7,0))) -> 198.14515
A10: Ano-base = 0 em Premissas!C6 usa a média 2022–2024.

Sheet CM_Frete
A1: Frete ferroviário porto -> usina — tarifas de referência ANTT (carvão mineral)
A2: Tarifa = parcela fixa (R$/t) + parcela variável (R$/t.km) x distância. Tarifas máximas homologadas pela ANTT, sem ICMS (Lei 13.673/2018). Distâncias somadas a partir dos marcos quilométricos das Declarações de Rede 2025 (MRS e EFVM) e do marco da estação Intendente Câmara (km 447 da EFVM). Células amarelas: editáveis.
A4: TARIFAS
A5: Ferrovia | B5: Fixa R$/t | C5: Variável R$/t.km | D5: Fonte
A6: MRS | B6: 7.63 | C6: 0.2589 | D6: CARVAO MINERAL, Deliberação ANTT nº 54/2024, vigente 29/07/2024–28/07/2025 (31/12/2024)
A7: EFVM | B7: 18.65 | C7: 0.1185 | D7: CARVÃO MINERAL, Deliberação ANTT nº 99/2022 (vigência 21/12/2022), simulador tarifário Vale
A8: Fator de atualização EFVM p/ ano-base | B8: 1.0967 | D8: IPCA 2023 (4,62%) x 2024 (4,83%). Usar 1,0 para manter a tabela como publicada. CONFERIR deliberação de reajuste EFVM vigente em 2024.
A10: FLUXOS
A11: Fluxo | B11: Ferrovia | C11: Distância km | D11: R$/t | E11: Fonte da distância
A12: Itaguaí -> Ouro Branco | B12: MRS | C12: 463 | D12: =($B$6+$C$6*C12) -> 127.5007 | E12: Soma de marcos km (DR MRS 2025): Itaguaí->Japeri ~30 + Japeri(km 64 L.Centro)->B.do Piraí(km 108) + B.do Piraí(km 108 L.SP)->Saudade(km 156) + F.do Aço/Ligação até Jeceaba (km 305) + Jeceaba(km 504 L.Centro)->Dr.J.Murtinho(km 478) + Ramal Açominas 9,6
A13: Itaguaí -> Volta Redonda | B13: MRS | C13: 111 | D13: =($B$6+$C$6*C13) -> 36.3679 | E13: Itaguaí->Japeri ~30 + Japeri->B.do Piraí 44 + B.do Piraí(km 108)->Volta Redonda(km 144,9 L.SP) 36,7
A14: Praia Mole -> Ipatinga | B14: EFVM | C14: 460 | D14: =($B$7+$C$7*C14)*$B$8 -> 80.234572 | E14: Marco km 447 da estação Intendente Câmara (EFVM) + Ramal Tubarão 12,4 (DR EFVM 2025)
A15: Praia Mole -> Monlevade | B15: EFVM | C15: 540 | D15: =($B$7+$C$7*C15)*$B$8 -> 90.631288 | E15: Estimativa: tronco até RH-77/Desemb. Drumond (km 507) + Drumond–Piçarrão 16 + trecho até Monlevade ~15 + Ramal Tubarão. REFINAR se necessário
A17: ADICIONAL POR UF (ponderado pela capacidade das plantas a carvão mineral)
A18: Planta | B18: UF | C18: Capacidade kt | D18: Frete R$/t | E18: Obs
A19: Gerdau Ouro Branco | B19: MG | C19: 7600 | D19: =D12 -> 127.5007 | E19: MRS
A20: Usiminas Ipatinga | B20: MG | C20: 3500 | D20: =D14 -> 80.234572 | E20: EFVM
A21: AM Monlevade | B21: MG | C21: 3500 | D21: =D15 -> 90.631288 | E21: EFVM
A22: CSN Volta Redonda | B22: RJ | C22: 4505 | D22: =D13 -> 36.3679 | E22: MRS
A23: Ternium Santa Cruz | B23: RJ | C23: 5000 | D23: 0 | E23: porto (Itaguaí/Sepetiba): frete 0
A24: AM Tubarão | B24: ES | C24: 7500 | D24: 0 | E24: porto (Praia Mole): frete 0
A25: AM Pecém | B25: CE | C25: 3000 | D25: 0 | E25: porto (Pecém): frete 0
A27: Adicional MG (R$/t) | D27: =SUMPRODUCT(($B$19:$B$25="MG")*$C$19:$C$25*$D$19:$D$25)/SUMIFS($C$19:$C$25,$B$19:$B$25,"MG") -> 107.33122
A28: Adicional RJ (R$/t) | D28: =SUMPRODUCT(($B$19:$B$25="RJ")*$C$19:$C$25*$D$19:$D$25)/SUMIFS($C$19:$C$25,$B$19:$B$25,"RJ") -> 17.236969
A29: Câmbio do ano-base (R$/US$) | D29: =Premissas!C23 -> 5.392
A30: Adicional MG (US$/t) | D30: =D27/D29 -> 19.905642
A31: Adicional RJ (US$/t) | D31: =D28/D29 -> 3.1967672
A33: Demais UFs: adicional 0 (hipótese: greenfield/planta litorânea recebe CIF no porto mais próximo). Documentado no LEIA-ME.

Sheet CM_por_UF
A1: Carvão metalúrgico — preço por UF (US$/GJ)
A2: Preço UF = CIF nacional do ano-base (CM_Comex) + adicional de frete ferroviário (CM_Frete), convertido por PCI (Premissas!C35). UFs sem planta a carvão ou litorâneas: adicional 0.
A4: UF | B4: Adicional frete US$/t | C4: Preço US$/t | D4: Preço US$/GJ
A5: AC | B5: 0 | C5: =CM_Comex!$D$9+B5 -> 198.14515 | D5: =C5/Premissas!$C$35 -> 6.3954263
A6: AL | B6: 0 | C6: =CM_Comex!$D$9+B6 -> 198.14515 | D6: =C6/Premissas!$C$35 -> 6.3954263
A7: AM | B7: 0 | C7: =CM_Comex!$D$9+B7 -> 198.14515 | D7: =C7/Premissas!$C$35 -> 6.3954263
A8: AP | B8: 0 | C8: =CM_Comex!$D$9+B8 -> 198.14515 | D8: =C8/Premissas!$C$35 -> 6.3954263
A9: BA | B9: 0 | C9: =CM_Comex!$D$9+B9 -> 198.14515 | D9: =C9/Premissas!$C$35 -> 6.3954263
A10: CE | B10: 0 | C10: =CM_Comex!$D$9+B10 -> 198.14515 | D10: =C10/Premissas!$C$35 -> 6.3954263
A11: DF | B11: 0 | C11: =CM_Comex!$D$9+B11 -> 198.14515 | D11: =C11/Premissas!$C$35 -> 6.3954263
A12: ES | B12: 0 | C12: =CM_Comex!$D$9+B12 -> 198.14515 | D12: =C12/Premissas!$C$35 -> 6.3954263
A13: GO | B13: 0 | C13: =CM_Comex!$D$9+B13 -> 198.14515 | D13: =C13/Premissas!$C$35 -> 6.3954263
A14: MA | B14: 0 | C14: =CM_Comex!$D$9+B14 -> 198.14515 | D14: =C14/Premissas!$C$35 -> 6.3954263
A15: MG | B15: =CM_Frete!D30 -> 19.905642 | C15: =CM_Comex!$D$9+B15 -> 218.05079 | D15: =C15/Premissas!$C$35 -> 7.0379102
A16: MS | B16: 0 | C16: =CM_Comex!$D$9+B16 -> 198.14515 | D16: =C16/Premissas!$C$35 -> 6.3954263
A17: MT | B17: 0 | C17: =CM_Comex!$D$9+B17 -> 198.14515 | D17: =C17/Premissas!$C$35 -> 6.3954263
A18: PA | B18: 0 | C18: =CM_Comex!$D$9+B18 -> 198.14515 | D18: =C18/Premissas!$C$35 -> 6.3954263
A19: PB | B19: 0 | C19: =CM_Comex!$D$9+B19 -> 198.14515 | D19: =C19/Premissas!$C$35 -> 6.3954263
A20: PE | B20: 0 | C20: =CM_Comex!$D$9+B20 -> 198.14515 | D20: =C20/Premissas!$C$35 -> 6.3954263
A21: PI | B21: 0 | C21: =CM_Comex!$D$9+B21 -> 198.14515 | D21: =C21/Premissas!$C$35 -> 6.3954263
A22: PR | B22: 0 | C22: =CM_Comex!$D$9+B22 -> 198.14515 | D22: =C22/Premissas!$C$35 -> 6.3954263
A23: RJ | B23: =CM_Frete!D31 -> 3.1967672 | C23: =CM_Comex!$D$9+B23 -> 201.34191 | D23: =C23/Premissas!$C$35 -> 6.4986067
A24: RN | B24: 0 | C24: =CM_Comex!$D$9+B24 -> 198.14515 | D24: =C24/Premissas!$C$35 -> 6.3954263
A25: RO | B25: 0 | C25: =CM_Comex!$D$9+B25 -> 198.14515 | D25: =C25/Premissas!$C$35 -> 6.3954263
A26: RR | B26: 0 | C26: =CM_Comex!$D$9+B26 -> 198.14515 | D26: =C26/Premissas!$C$35 -> 6.3954263
A27: RS | B27: 0 | C27: =CM_Comex!$D$9+B27 -> 198.14515 | D27: =C27/Premissas!$C$35 -> 6.3954263
A28: SC | B28: 0 | C28: =CM_Comex!$D$9+B28 -> 198.14515 | D28: =C28/Premissas!$C$35 -> 6.3954263
A29: SE | B29: 0 | C29: =CM_Comex!$D$9+B29 -> 198.14515 | D29: =C29/Premissas!$C$35 -> 6.3954263
A30: SP | B30: 0 | C30: =CM_Comex!$D$9+B30 -> 198.14515 | D30: =C30/Premissas!$C$35 -> 6.3954263
A31: TO | B31: 0 | C31: =CM_Comex!$D$9+B31 -> 198.14515 | D31: =C31/Premissas!$C$35 -> 6.3954263

Sheet Diesel_por_UF
A1: Óleo diesel — preço por UF (US$/GJ), método da razão
A2: Estrutura: ANP, Levantamento de Preços de Combustíveis (SLP), preço médio de REVENDA de ÓLEO DIESEL (B S500), média simples das semanas de 2024, por UF. Nível: preço nacional do Model_Config (Premissas!C39), pois revenda inclui margem varejista que o consumidor industrial não paga. Preço UF = (R$/L da UF ÷ média nacional simples) x nível nacional. Mesma lógica do gás natural (estrutura de uma fonte, nível de outra).
A4: UF | B4: R$/L 2024 (ANP) | C4: Razão vs nacional | D4: Preço US$/GJ
A5: AC | B5: 7.325 | C5: =B5/$B$33 -> 1.2086794 | D5: =C5*Premissas!$C$39 -> 26.590947
A6: AL | B6: 6.035 | C6: =B6/$B$33 -> 0.99581981 | D6: =C6*Premissas!$C$39 -> 21.908036
A7: AM | B7: 6.284 | C7: =B7/$B$33 -> 1.0369067 | D7: =C7*Premissas!$C$39 -> 22.811947
A8: AP | B8: 6.467 | C8: =B8/$B$33 -> 1.067103 | D8: =C8*Premissas!$C$39 -> 23.476266
A9: BA | B9: 5.941 | C9: =B9/$B$33 -> 0.98030911 | D9: =C9*Premissas!$C$39 -> 21.566801
A10: CE | B10: 6.171 | C10: =B10/$B$33 -> 1.0182608 | D10: =C10*Premissas!$C$39 -> 22.401738
A11: DF | B11: 5.828 | C11: =B11/$B$33 -> 0.96166327 | D11: =C11*Premissas!$C$39 -> 21.156592
A12: ES | B12: 5.883 | C12: =B12/$B$33 -> 0.97073868 | D12: =C12*Premissas!$C$39 -> 21.356251
A13: GO | B13: 5.823 | C13: =B13/$B$33 -> 0.96083824 | D13: =C13*Premissas!$C$39 -> 21.138441
A14: MA | B14: 5.812 | C14: =B14/$B$33 -> 0.95902316 | D14: =C14*Premissas!$C$39 -> 21.098509
A15: MG | B15: 5.78 | C15: =B15/$B$33 -> 0.95374292 | D15: =C15*Premissas!$C$39 -> 20.982344
A16: MS | B16: 5.934 | C16: =B16/$B$33 -> 0.97915406 | D16: =C16*Premissas!$C$39 -> 21.541389
... A31: TO | B31: 5.862 | C31: =B31/$B$33 -> 0.96727353 | D31: =C31*Premissas!$C$39 -> 21.280018
A33: Média nacional simples (R$/L) | B33: =AVERAGE(B5:B31) -> 6.0603333
A34: Fonte: semanal-estados-desde-2013.xlsx (ANP), produto OLEO DIESEL, 2024. Valores agregados a partir das ~113 mil linhas do arquivo original.

Sheet H2_por_UF
A1: Hidrogênio eletrolítico — preço por UF (US$/GJ), razão amortecida sobre eletricidade
A2: Estrutura: coluna de eletricidade por UF desta planilha (EE_por_UF, ANEEL A4). Nível: preço nacional do Model_Config (Premissas!C42). H2(UF) = nível x [alfa x razão_EE + (1-alfa)], alfa = fração eletricidade no LCOH (Premissas!C43). Ressalva metodológica: tarifa de rede A4 difere de PPA renovável dedicado de hub; a razão captura a estrutura relativa entre UFs, não o nível absoluto de projeto. A elegibilidade geográfica do DR-H2 (UFs com hub) é tratada no script (H2_ALLOWED_STATES), não no preço.
A4: UF | B4: EE US$/GJ | C4: Razão EE vs nacional | D4: Preço H2 US$/GJ
A5: AC | B5: =EE_por_UF!J5 -> 24.432976 | C5: =B5/$B$33 -> 0.85638142 | D5: =Premissas!$C$42*(Premissas!$C$43*C5+(1-Premissas!$C$43)) -> 37.298336
A6: AL | B6: =EE_por_UF!J6 -> 30.929157 | C6: =B6/$B$33 -> 1.0840741 | D6: =Premissas!$C$42*(Premissas!$C$43*C6+(1-Premissas!$C$43)) -> 44.118187
A7: AM | B7: =EE_por_UF!J7 -> 36.82022 | C7: =B7/$B$33 -> 1.2905572 | D7: =Premissas!$C$42*(Premissas!$C$43*C7+(1-Premissas!$C$43)) -> 50.302769
A8: AP | B8: =EE_por_UF!J8 -> 29.359478 | C8: =B8/$B$33 -> 1.0290565 | D8: =Premissas!$C$42*(Premissas!$C$43*C8+(1-Premissas!$C$43)) -> 42.470299
A9: BA | B9: =EE_por_UF!J9 -> 28.22157 | C9: =B9/$B$33 -> 0.98917253 | D9: =Premissas!$C$42*(Premissas!$C$43*C9+(1-Premissas!$C$43)) -> 41.275696
A10: CE | B10: =EE_por_UF!J10 -> 25.120381 | C10: =B10/$B$33 -> 0.88047512 | D10: =Premissas!$C$42*(Premissas!$C$43*C10+(1-Premissas!$C$43)) -> 38.019991
A11: DF | B11: =EE_por_UF!J11 -> 34.21652 | C11: =B11/$B$33 -> 1.1992969 | D11: =Premissas!$C$42*(Premissas!$C$43*C11+(1-Premissas!$C$43)) -> 47.569341
A12: ES | B12: =EE_por_UF!J12 -> 29.508837 | C12: =B12/$B$33 -> 1.0342915 | D12: =Premissas!$C$42*(Premissas!$C$43*C12+(1-Premissas!$C$43)) -> 42.627099
A13: GO | B13: =EE_por_UF!J13 -> 26.458341 | C13: =B13/$B$33 -> 0.92737094 | D13: =Premissas!$C$42*(Premissas!$C$43*C13+(1-Premissas!$C$43)) -> 39.424614
A14: MA | B14: =EE_por_UF!J14 -> 24.021002 | C14: =B14/$B$33 -> 0.84194166 | D14: =Premissas!$C$42*(Premissas!$C$43*C14+(1-Premissas!$C$43)) -> 36.865837
A15: MG | B15: =EE_por_UF!J15 -> 30.406573 | C15: =B15/$B$33 -> 1.0657574 | D15: =Premissas!$C$42*(Premissas!$C$43*C15+(1-Premissas!$C$43)) -> 43.569565
A16: MS | B16: =EE_por_UF!J16 -> 31.73135 | C16: =B16/$B$33 -> 1.1121911 | D16: =Premissas!$C$42*(Premissas!$C$43*C16+(1-Premissas!$C$43)) -> 44.960348
... A31: TO | B31: =EE_por_UF!J31 -> 26.474068 | C31: =B31/$B$33 -> 0.92792218 | D31: =Premissas!$C$42*(Premissas!$C$43*C31+(1-Premissas!$C$43)) -> 39.441125
A33: Média nacional simples EE (US$/GJ) | B33: =AVERAGE(B5:B31) -> 28.530483

Sheet Minerio_ANM
A1: Minério de ferro — preço implícito na mina por UF (ANM, Anuário Mineral Brasileiro)
A2: PENDENTE DOWNLOAD: gov.br/anm -> Anuário Mineral (ou dados abertos ANM, CSV). Tabela "Produção Mineral Comercializada — quantidade e valor", substância FERRO, por UF, última edição. Preço implícito = Valor ÷ Quantidade. Preencher células amarelas; anotar edição/ano-base na coluna Fonte.
A4: UF | B4: Produção comercializada (t) | C4: Valor (R$) | D4: R$/t | E4: US$/t | F4: Fonte (edição AMB)
A5: MG | D5: =IF(OR(B5="",C5=""),"",C5/B5) | E5: =IF(D5="","",D5/Premissas!$C$23)
A6: PA | D6: =IF(OR(B6="",C6=""),"",C6/B6) | E6: =IF(D6="","",D6/Premissas!$C$23)
A7: ES | D7: =IF(OR(B7="",C7=""),"",C7/B7) | E7: =IF(D7="","",D7/Premissas!$C$23)
A8: BA | D8: =IF(OR(B8="",C8=""),"",C8/B8) | E8: =IF(D8="","",D8/Premissas!$C$23)
A9: MS | D9: =IF(OR(B9="",C9=""),"",C9/B9) | E9: =IF(D9="","",D9/Premissas!$C$23)
A11: Diferencial PA - MG (US$/t) | E11: =IFERROR(E6-E5,0) -> 0
A12: Enquanto vazio, o diferencial retorna 0 e o modelo roda sem o efeito preço-de-mina.

Sheet Pelota_Comex
A1: Pelota de minério de ferro — FOB de exportação por UF de origem (Comex Stat, NCM 2601.12.00)
A2: PENDENTE DOWNLOAD: comexstat.mdic.gov.br -> Exportação -> consulta detalhada. NCM 2601.12.00 (aglomerados/pelotas), detalhe por UF DE ORIGEM (ES = Tubarão; MA = São Luís), métricas US$ FOB e kg líquido, anos 2022-2024. Geografia da aglomeração: 11 pelotizadoras no Brasil — 8 ES, 2 MG, 1 MA (São Luís, insumo de Carajás/PA).
A4: UF origem | B4: Ano | C4: US$ FOB | D4: kg líquido | E4: FOB US$/t | F4: Fonte
A5: ES | B5: 2022 | E5: =IF(OR(C5="",D5=""),"",C5/D5*1000)
A6: ES | B6: 2023 | E6: =IF(OR(C6="",D6=""),"",C6/D6*1000)
A7: ES | B7: 2024 | E7: =IF(OR(C7="",D7=""),"",C7/D7*1000)
A8: MA | B8: 2022 | E8: =IF(OR(C8="",D8=""),"",C8/D8*1000)
A9: MA | B9: 2023 | E9: =IF(OR(C9="",D9=""),"",C9/D9*1000)
A10: MA | B10: 2024 | E10: =IF(OR(C10="",D10=""),"",C10/D10*1000)
A12: FOB ano-base ES (US$/t) | E12: =IFERROR(IF(Premissas!C6=0,AVERAGE(E5:E7),INDEX(E5:E7,MATCH(Premissas!C6,B5:B7,0))),"")
A13: FOB ano-base MA (US$/t) | E13: =IFERROR(IF(Premissas!C6=0,AVERAGE(E8:E10),INDEX(E8:E10,MATCH(Premissas!C6,B8:B10,0))),"")
A14: Delta MA - ES (US$/t pelota) | E14: =IFERROR(E13-E12,0) -> 0

Sheet Ore_Frete
A1: Frete ferroviário de minério mina -> usina — tarifas de referência ANTT
A2: Mesmas fontes e estrutura do carvão (CM_Frete): tarifa = fixa + variável x distância, sem ICMS. Fluxos que definem o adicional das UFs não-âncora. MG = âncora (delta 0; fretes intraestaduais curtos desprezados, documentado nas Premissas).
A4: TARIFAS — MINÉRIO DE FERRO
A5: Ferrovia | B5: Fixa R$/t | C5: Variável R$/t.km | D5: Fonte
A6: MRS | B6: 7.63 | C6: 0.1639 | D6: MINERIO DE FERRO, Deliberação ANTT nº 54/2024 (vigente 31/12/2024), tabela MRS
A7: EFVM | B7: 16.03 | C7: 0.0831 | D7: MINÉRIO DE FERRO, Deliberação ANTT nº 99/2022 (vigência 21/12/2022), simulador tarifário Vale
A8: Fator de atualização EFVM | B8: =CM_Frete!B8 -> 1.0967 | D8: Mesmo fator do carvão (CM_Frete!B8) — uma decisão, um lugar
A10: FLUXOS
A11: Fluxo | B11: Ferrovia | C11: Distância km | D11: R$/t | E11: Fonte da distância
A12: Itabira -> Tubarão (usina ES) | B12: EFVM | C12: 550 | D12: =($B$7+$C$7*C12)*$B$8 -> 67.704774 | E12: Tronco EFVM até Itabira (km 541, DR EFVM 2025) + Ramal Tubarão ~12
A13: Casa de Pedra -> Volta Redonda | B13: MRS | C13: 340 | D13: =($B$6+$C$6*C13) -> 63.356 | E13: Congonhas/Dr.J.Murtinho (km ~478 L.Centro) -> Jeceaba (504) -> F.do Aço (305) -> Saudade -> VR (km 144,9 L.SP). Estimativa por marcos — REFINAR
A14: Casa de Pedra -> Itaguaí (Sta Cruz) | B14: MRS | C14: 450 | D14: =($B$6+$C$6*C14) -> 81.385 | E14: Idem até Saudade + Saudade -> B.do Piraí -> Japeri -> Itaguaí (~122). Estimativa por marcos — REFINAR
A16: ADICIONAL POR UF (ponderado por capacidade)
A17: Planta | B17: UF | C17: Capacidade kt | D17: Frete R$/t
A18: AM Tubarão | B18: ES | C18: 7500 | D18: =D12 -> 67.704774
A19: CSN Volta Redonda | B19: RJ | C19: 4505 | D19: =D13 -> 63.356
A20: Ternium Santa Cruz | B20: RJ | C20: 5000 | D20: =D14 -> 81.385
A22: Adicional ES (R$/t) | D22: =D18 -> 67.704774
A23: Adicional RJ (R$/t) | D23: =(C19*D19+C20*D20)/(C19+C20) -> 72.839956
A24: Câmbio do ano-base | D24: =Premissas!C23 -> 5.392
A25: Adicional ES (US$/t) | D25: =D22/D24 -> 12.556523
A26: Adicional RJ (US$/t) | D26: =D23/D24 -> 13.508894

Sheet Ore_por_UF
A1: Minério e pelota — diferenciais por UF (método delta, duas âncoras)
A2: Delta = intensidade x diferença de custo do insumo vs. âncora. Família BF/IBT: minério comum, âncora MG. Família DR: pelota DR-grade, âncora ES (Tubarão). EAF: imune (sem minério). UFs sem fluxo estimado: 0 por hipótese, documentado. Células vazias/0 com PENDENTE nas abas de origem não travam o modelo.
A4: UF | B4: Frete minério US$/t | C4: Dif. mina ANM US$/t | D4: Total minério US$/t | E4: Delta BF/IBT US$/t aço | F4: Adicional pelota US$/t | G4: Delta DR US$/t aço | H4: Nota
A5: AC | B5: 0 | C5: 0 | D5: =B5+C5 -> 0 | E5: =D5*Premissas!$C$47 -> 0 | F5: 0 | G5: =F5*Premissas!$C$48 -> 0
A6: AL | B6: 0 | C6: 0 | D6: =B6+C6 -> 0 | E6: =D6*Premissas!$C$47 -> 0 | F6: 0 | G6: =F6*Premissas!$C$48 -> 0
A7: AM | B7: 0 | C7: 0 | D7: =B7+C7 -> 0 | E7: =D7*Premissas!$C$47 -> 0 | F7: 0 | G7: =F7*Premissas!$C$48 -> 0
A8: AP | B8: 0 | C8: 0 | D8: =B8+C8 -> 0 | E8: =D8*Premissas!$C$47 -> 0 | F8: 0 | G8: =F8*Premissas!$C$48 -> 0
A9: BA | B9: 0 | C9: 0 | D9: =B9+C9 -> 0 | E9: =D9*Premissas!$C$47 -> 0 | F9: 0 | G9: =F9*Premissas!$C$48 -> 0
A10: CE | B10: =Premissas!$C$49 -> 0 | C10: 0 | D10: =B10+C10 -> 0 | E10: =D10*Premissas!$C$47 -> 0 | F10: =Premissas!$C$49 -> 0 | G10: =F10*Premissas!$C$48 -> 0 | H10: Minério e pelota via cabotagem (Ponta da Madeira/Tubarão) — premissa pendente
A11: DF | B11: 0 | C11: 0 | D11: =B11+C11 -> 0 | E11: =D11*Premissas!$C$47 -> 0 | F11: 0 | G11: =F11*Premissas!$C$48 -> 0
A12: ES | B12: =Ore_Frete!D25 -> 12.556523 | C12: 0 | D12: =B12+C12 -> 12.556523 | E12: =D12*Premissas!$C$47 -> 20.090438 | F12: 0 | G12: =F12*Premissas!$C$48 -> 0 | H12: Frete EFVM Itabira->Tubarão; âncora família DR (pelota na fonte)
A13: GO | B13: 0 | C13: 0 | D13: =B13+C13 -> 0 | E13: =D13*Premissas!$C$47 -> 0 | F13: 0 | G13: =F13*Premissas!$C$48 -> 0
A14: MA | B14: 0 | C14: 0 | D14: =B14+C14 -> 0 | E14: =D14*Premissas!$C$47 -> 0 | F14: =Pelota_Comex!E14 -> 0 | G14: =F14*Premissas!$C$48 -> 0 | H14: Pelota na fonte (São Luís): delta = FOB SL - FOB Tubarão (Comex)
A15: MG | B15: 0 | C15: 0 | D15: =B15+C15 -> 0 | E15: =D15*Premissas!$C$47 -> 0 | F15: 0 | G15: =F15*Premissas!$C$48 -> 0 | H15: Âncora família BF/IBT (delta 0)
A16: MS | B16: 0 | C16: 0 | D16: =B16+C16 -> 0 | E16: =D16*Premissas!$C$47 -> 0 | F16: 0 | G16: =F16*Premissas!$C$48 -> 0
A17: MT | B17: 0 | C17: 0 | D17: =B17+C17 -> 0 | E17: =D17*Premissas!$C$47 -> 0 | F17: 0 | G17: =F17*Premissas!$C$48 -> 0
A18: PA | B18: 0 | C18: =Minerio_ANM!E11 -> 0 | D18: =B18+C18 -> 0 | E18: =D18*Premissas!$C$47 -> 0 | F18: 0 | G18: =F18*Premissas!$C$48 -> 0 | H18: Diferencial preço de mina Carajás vs MG (ANM) — pendente
A19: PB | B19: 0 | C19: 0 | D19: =B19+C19 -> 0 | E19: =D19*Premissas!$C$47 -> 0 | F19: 0 | G19: =F19*Premissas!$C$48 -> 0
A20: PE | B20: 0 | C20: 0 | D20: =B20+C20 -> 0 | E20: =D20*Premissas!$C$47 -> 0 | F20: 0 | G20: =F20*Premissas!$C$48 -> 0
A21: PI | B21: 0 | C21: 0 | D21: =B21+C21 -> 0 | E21: =D21*Premissas!$C$47 -> 0 | F21: 0 | G21: =F21*Premissas!$C$48 -> 0
A22: PR | B22: 0 | C22: 0 | D22: =B22+C22 -> 0 | E22: =D22*Premissas!$C$47 -> 0 | F22: 0 | G22: =F22*Premissas!$C$48 -> 0
A23: RJ | B23: =Ore_Frete!D26 -> 13.508894 | C23: 0 | D23: =B23+C23 -> 13.508894 | E23: =D23*Premissas!$C$47 -> 21.61423 | F23: =Premissas!$C$49 -> 0 | G23: =F23*Premissas!$C$48 -> 0 | H23: Frete MRS Casa de Pedra (ponderado VR/Sta Cruz); pelota via cabotagem de Tubarão
A24: RN | B24: 0 | C24: 0 | D24: =B24+C24 -> 0 | E24: =D24*Premissas!$C$47 -> 0 | F24: 0 | G24: =F24*Premissas!$C$48 -> 0
A25: RO | B25: 0 | C25: 0 | D25: =B25+C25 -> 0 | E25: =D25*Premissas!$C$47 -> 0 | F25: 0 | G25: =F25*Premissas!$C$48 -> 0
A26: RR | B26: 0 | C26: 0 | D26: =B26+C26 -> 0 | E26: =D26*Premissas!$C$47 -> 0 | F26: 0 | G26: =F26*Premissas!$C$48 -> 0
A27: RS | B27: 0 | C27: 0 | D27: =B27+C27 -> 0 | E27: =D27*Premissas!$C$47 -> 0 | F27: 0 | G27: =F27*Premissas!$C$48 -> 0
A28: SC | B28: 0 | C28: 0 | D28: =B28+C28 -> 0 | E28: =D28*Premissas!$C$47 -> 0 | F28: 0 | G28: =F28*Premissas!$C$48 -> 0
A29: SE | B29: 0 | C29: 0 | D29: =B29+C29 -> 0 | E29: =D29*Premissas!$C$47 -> 0 | F29: 0 | G29: =F29*Premissas!$C$48 -> 0
A30: SP | B30: 0 | C30: 0 | D30: =B30+C30 -> 0 | E30: =D30*Premissas!$C$47 -> 0 | F30: 0 | G30: =F30*Premissas!$C$48 -> 0
A31: TO | B31: 0 | C31: 0 | D31: =B31+C31 -> 0 | E31: =D31*Premissas!$C$47 -> 0 | F31: 0 | G31: =F31*Premissas!$C$48 -> 0

Sheet Ore_Cost_State
A1: Route | B1: State | C1: Extra_cost_USD_per_t | D1: Source_note | F1: SAÍDA — nova aba Ore_Cost_State no Model_Config_12 (copie A1:D163). Rotas ausentes (EAF) = sem delta. Requer novo bloco de leitura + termo na função objetivo do v20_13.
A2: BF-BOF MC | B2: AC | C2: =Ore_por_UF!E5 -> 0 | D2: Delta minério comum vs âncora MG: frete ANTT (MRS/EFVM) + dif. mina ANM; intensidade 1,6 t/t
A3: BF-BOF MC | B3: AL | C3: =Ore_por_UF!E6 -> 0 | D3: Delta minério comum vs âncora MG: frete ANTT (MRS/EFVM) + dif. mina ANM; intensidade 1,6 t/t
A4: BF-BOF MC | B4: AM | C4: =Ore_por_UF!E7 -> 0 | D4: Delta minério comum vs âncora MG: frete ANTT (MRS/EFVM) + dif. mina ANM; intensidade 1,6 t/t
A5: BF-BOF MC | B5: AP | C5: =Ore_por_UF!E8 -> 0 | D5: Delta minério comum vs âncora MG: frete ANTT (MRS/EFVM) + dif. mina ANM; intensidade 1,6 t/t
A6: BF-BOF MC | B6: BA | C6: =Ore_por_UF!E9 -> 0 | D6: Delta minério comum vs âncora MG: frete ANTT (MRS/EFVM) + dif. mina ANM; intensidade 1,6 t/t
A7: BF-BOF MC | B7: CE | C7: =Ore_por_UF!E10 -> 0 | D7: Delta minério comum vs âncora MG: frete ANTT (MRS/EFVM) + dif. mina ANM; intensidade 1,6 t/t
A8: BF-BOF MC | B8: DF | C8: =Ore_por_UF!E11 -> 0 | D8: Delta minério comum vs âncora MG: frete ANTT (MRS/EFVM) + dif. mina ANM; intensidade 1,6 t/t
A9: BF-BOF MC | B9: ES | C9: =Ore_por_UF!E12 -> 20.090438 | D9: Delta minério comum vs âncora MG: frete ANTT (MRS/EFVM) + dif. mina ANM; intensidade 1,6 t/t
A10: BF-BOF MC | B10: GO | C10: =Ore_por_UF!E13 -> 0 | D10: Delta minério comum vs âncora MG: frete ANTT (MRS/EFVM) + dif. mina ANM; intensidade 1,6 t/t
A11: BF-BOF MC | B11: MA | C11: =Ore_por_UF!E14 -> 0 | D11: Delta minério comum vs âncora MG: frete ANTT (MRS/EFVM) + dif. mina ANM; intensidade 1,6 t/t
A12: BF-BOF MC | B12: MG | C12: =Ore_por_UF!E15 -> 0 | D12: Delta minério comum vs âncora MG: frete ANTT (MRS/EFVM) + dif. mina ANM; intensidade 1,6 t/t
A13: BF-BOF MC | B13: MS | C13: =Ore_por_UF!E16 -> 0 | D13: Delta minério comum vs âncora MG: frete ANTT (MRS/EFVM) + dif. mina ANM; intensidade 1,6 t/t
... A28: BF-BOF MC | B28: TO | C28: =Ore_por_UF!E31 -> 0 | D28: Delta minério comum vs âncora MG: frete ANTT (MRS/EFVM) + dif. mina ANM; intensidade 1,6 t/t
A29: BF-BOF CC | B29: AC | C29: =Ore_por_UF!E5 -> 0 | D29: Delta minério comum vs âncora MG: frete ANTT (MRS/EFVM) + dif. mina ANM; intensidade 1,6 t/t
A30: BF-BOF CC | B30: AL | C30: =Ore_por_UF!E6 -> 0 | D30: Delta minério comum vs âncora MG: frete ANTT (MRS/EFVM) + dif. mina ANM; intensidade 1,6 t/t
A31: BF-BOF CC | B31: AM | C31: =Ore_por_UF!E7 -> 0 | D31: Delta minério comum vs âncora MG: frete ANTT (MRS/EFVM) + dif. mina ANM; intensidade 1,6 t/t
A32: BF-BOF CC | B32: AP | C32: =Ore_por_UF!E8 -> 0 | D32: Delta minério comum vs âncora MG: frete ANTT (MRS/EFVM) + dif. mina ANM; intensidade 1,6 t/t
A33: BF-BOF CC | B33: BA | C33: =Ore_por_UF!E9 -> 0 | D33: Delta minério comum vs âncora MG: frete ANTT (MRS/EFVM) + dif. mina ANM; intensidade 1,6 t/t
A34: BF-BOF CC | B34: CE | C34: =Ore_por_UF!E10 -> 0 | D34: Delta minério comum vs âncora MG: frete ANTT (MRS/EFVM) + dif. mina ANM; intensidade 1,6 t/t
A35: BF-BOF CC | B35: DF | C35: =Ore_por_UF!E11 -> 0 | D35: Delta minério comum vs âncora MG: frete ANTT (MRS/EFVM) + dif. mina ANM; intensidade 1,6 t/t
A36: BF-BOF CC | B36: ES | C36: =Ore_por_UF!E12 -> 20.090438 | D36: Delta minério comum vs âncora MG: frete ANTT (MRS/EFVM) + dif. mina ANM; intensidade 1,6 t/t
A37: BF-BOF CC | B37: GO | C37: =Ore_por_UF!E13 -> 0 | D37: Delta minério comum vs âncora MG: frete ANTT (MRS/EFVM) + dif. mina ANM; intensidade 1,6 t/t
A38: BF-BOF CC | B38: MA | C38: =Ore_por_UF!E14 -> 0 | D38: Delta minério comum vs âncora MG: frete ANTT (MRS/EFVM) + dif. mina ANM; intensidade 1,6 t/t
A39: BF-BOF CC | B39: MG | C39: =Ore_por_UF!E15 -> 0 | D39: Delta minério comum vs âncora MG: frete ANTT (MRS/EFVM) + dif. mina ANM; intensidade 1,6 t/t
A40: BF-BOF CC | B40: MS | C40: =Ore_por_UF!E16 -> 0 | D40: Delta minério comum vs âncora MG: frete ANTT (MRS/EFVM) + dif. mina ANM; intensidade 1,6 t/t
... A55: BF-BOF CC | B55: TO | C55: =Ore_por_UF!E31 -> 0 | D55: Delta minério comum vs âncora MG: frete ANTT (MRS/EFVM) + dif. mina ANM; intensidade 1,6 t/t
A56: BF-BOF-CCS | B56: AC | C56: =Ore_por_UF!E5 -> 0 | D56: Delta minério comum vs âncora MG: frete ANTT (MRS/EFVM) + dif. mina ANM; intensidade 1,6 t/t
A57: BF-BOF-CCS | B57: AL | C57: =Ore_por_UF!E6 -> 0 | D57: Delta minério comum vs âncora MG: frete ANTT (MRS/EFVM) + dif. mina ANM; intensidade 1,6 t/t
A58: BF-BOF-CCS | B58: AM | C58: =Ore_por_UF!E7 -> 0 | D58: Delta minério comum vs âncora MG: frete ANTT (MRS/EFVM) + dif. mina ANM; intensidade 1,6 t/t
A59: BF-BOF-CCS | B59: AP | C59: =Ore_por_UF!E8 -> 0 | D59: Delta minério comum vs âncora MG: frete ANTT (MRS/EFVM) + dif. mina ANM; intensidade 1,6 t/t
A60: BF-BOF-CCS | B60: BA | C60: =Ore_por_UF!E9 -> 0 | D60: Delta minério comum vs âncora MG: frete ANTT (MRS/EFVM) + dif. mina ANM; intensidade 1,6 t/t
A61: BF-BOF-CCS | B61: CE | C61: =Ore_por_UF!E10 -> 0 | D61: Delta minério comum vs âncora MG: frete ANTT (MRS/EFVM) + dif. mina ANM; intensidade 1,6 t/t
A62: BF-BOF-CCS | B62: DF | C62: =Ore_por_UF!E11 -> 0 | D62: Delta minério comum vs âncora MG: frete ANTT (MRS/EFVM) + dif. mina ANM; intensidade 1,6 t/t
A63: BF-BOF-CCS | B63: ES | C63: =Ore_por_UF!E12 -> 20.090438 | D63: Delta minério comum vs âncora MG: frete ANTT (MRS/EFVM) + dif. mina ANM; intensidade 1,6 t/t
A64: BF-BOF-CCS | B64: GO | C64: =Ore_por_UF!E13 -> 0 | D64: Delta minério comum vs âncora MG: frete ANTT (MRS/EFVM) + dif. mina ANM; intensidade 1,6 t/t
A65: BF-BOF-CCS | B65: MA | C65: =Ore_por_UF!E14 -> 0 | D65: Delta minério comum vs âncora MG: frete ANTT (MRS/EFVM) + dif. mina ANM; intensidade 1,6 t/t
A66: BF-BOF-CCS | B66: MG | C66: =Ore_por_UF!E15 -> 0 | D66: Delta minério comum vs âncora MG: frete ANTT (MRS/EFVM) + dif. mina ANM; intensidade 1,6 t/t
A67: BF-BOF-CCS | B67: MS | C67: =Ore_por_UF!E16 -> 0 | D67: Delta minério comum vs âncora MG: frete ANTT (MRS/EFVM) + dif. mina ANM; intensidade 1,6 t/t
... A82: BF-BOF-CCS | B82: TO | C82: =Ore_por_UF!E31 -> 0 | D82: Delta minério comum vs âncora MG: frete ANTT (MRS/EFVM) + dif. mina ANM; intensidade 1,6 t/t
...

Sheet Fuel_Prices_State
A1: Fuel | B1: State | C1: Price_USD_per_GJ | D1: Source_note | F1: SAÍDA — copie A1:D136 e cole na aba Fuel_Prices_State do Model_Config_12
A2: Eletricidade | B2: AC | C2: =EE_por_UF!J5 -> 24.432976 | D2: =IF(EE_por_UF!K5="","ANEEL A4 verde fora ponta TUSD+TE + demanda, tributos: "&Premissas!$C$19&", ano-base "&Premissas!$C$6,"Sem distribuidora atribuida a esta UF — media nacional. VERIFICAR mapeamento em EE_ANEEL.") -> ANEEL A4 verde fora ponta TUSD+TE + demanda, tributos: COM, ano-base 2024
A3: Eletricidade | B3: AL | C3: =EE_por_UF!J6 -> 30.929157 | D3: =IF(EE_por_UF!K6="","ANEEL A4 verde fora ponta TUSD+TE + demanda, tributos: "&Premissas!$C$19&", ano-base "&Premissas!$C$6,"Sem distribuidora atribuida a esta UF — media nacional. VERIFICAR mapeamento em EE_ANEEL.") -> ANEEL A4 verde fora ponta TUSD+TE + demanda, tributos: COM, ano-base 2024
A4: Eletricidade | B4: AM | C4: =EE_por_UF!J7 -> 36.82022 | D4: =IF(EE_por_UF!K7="","ANEEL A4 verde fora ponta TUSD+TE + demanda, tributos: "&Premissas!$C$19&", ano-base "&Premissas!$C$6,"Sem distribuidora atribuida a esta UF — media nacional. VERIFICAR mapeamento em EE_ANEEL.") -> ANEEL A4 verde fora ponta TUSD+TE + demanda, tributos: COM, ano-base 2024
A5: Eletricidade | B5: AP | C5: =EE_por_UF!J8 -> 29.359478 | D5: =IF(EE_por_UF!K8="","ANEEL A4 verde fora ponta TUSD+TE + demanda, tributos: "&Premissas!$C$19&", ano-base "&Premissas!$C$6,"Sem distribuidora atribuida a esta UF — media nacional. VERIFICAR mapeamento em EE_ANEEL.") -> ANEEL A4 verde fora ponta TUSD+TE + demanda, tributos: COM, ano-base 2024
A6: Eletricidade | B6: BA | C6: =EE_por_UF!J9 -> 28.22157 | D6: =IF(EE_por_UF!K9="","ANEEL A4 verde fora ponta TUSD+TE + demanda, tributos: "&Premissas!$C$19&", ano-base "&Premissas!$C$6,"Sem distribuidora atribuida a esta UF — media nacional. VERIFICAR mapeamento em EE_ANEEL.") -> ANEEL A4 verde fora ponta TUSD+TE + demanda, tributos: COM, ano-base 2024
